<?xml version="1.0"?>
<robot name="car" xmlns:xacro="http://www.ros.org/wiki/xacro">
  
  <!-- Gazebo 插件：关节状态发布（四个轮子都发布） -->
  <gazebo>
    <plugin name="gazebo_ros_joint_state_publisher" filename="libgazebo_ros_joint_state_publisher.so">
      <ros>
        <namespace>/</namespace>
        <remapping>~/out:=joint_states</remapping>
      </ros>
      <update_rate>30</update_rate>
      <joint_name>front_left_wheel_joint</joint_name>
      <joint_name>front_right_wheel_joint</joint_name>
      <joint_name>rear_left_wheel_joint</joint_name>
      <joint_name>rear_right_wheel_joint</joint_name>
    </plugin>
  </gazebo>
  
  <!-- 差速驱动插件：只驱动前轮！ -->
  <gazebo>
    <plugin name="diff_drive" filename="libgazebo_ros_diff_drive.so">
      <ros>
        <namespace>/</namespace>
        <remapping>cmd_vel:=cmd_vel</remapping>
      </ros>
      <!-- 只驱动前轮 -->
      <left_joint>front_left_wheel_joint</left_joint>
      <right_joint>front_right_wheel_joint</right_joint>
      <!-- 后轮不列入驱动列表，它们会作为从动轮自然旋转 -->
      <wheel_separation>0.34</wheel_separation>
      <wheel_diameter>0.1</wheel_diameter>
      <max_wheel_torque>20</max_wheel_torque>      <!-- 适当增加扭矩 -->
      <max_wheel_acceleration>1.5</max_wheel_acceleration>
      <command_topic>cmd_vel</command_topic>
      <odometry_topic>odom</odometry_topic>
      <odometry_frame>odom</odometry_frame>
      <robot_base_frame>base_footprint</robot_base_frame>
      <publish_odom>true</publish_odom>
      <publish_odom_tf>true</publish_odom_tf>
      <publish_wheel_tf>false</publish_wheel_tf>
    </plugin>
  </gazebo>
  
  <!-- 材质颜色等保持不变 -->
  <gazebo reference="base_link">
    <material>Gazebo/Blue</material>
  </gazebo>
  <gazebo reference="front_left_wheel_link">
    <material>Gazebo/Black</material>
  </gazebo>
  <gazebo reference="front_right_wheel_link">
    <material>Gazebo/Black</material>
  </gazebo>
  <gazebo reference="rear_left_wheel_link">
    <material>Gazebo/Black</material>
  </gazebo>
  <gazebo reference="rear_right_wheel_link">
    <material>Gazebo/Black</material>
  </gazebo>
  <gazebo reference="laser_link">
    <material>Gazebo/Red</material>
  </gazebo>
  
  <!-- 为所有轮子添加适当的摩擦系数（避免打滑） -->
  <gazebo reference="front_left_wheel_link">
    <mu1>1.0</mu1>
    <mu2>1.0</mu2>
    <kp>1000000.0</kp>
    <kd>10.0</kd>
  </gazebo>
  <gazebo reference="front_right_wheel_link">
    <mu1>1.0</mu1>
    <mu2>1.0</mu2>
    <kp>1000000.0</kp>
    <kd>10.0</kd>
  </gazebo>
  <gazebo reference="rear_left_wheel_link">
    <mu1>0.8</mu1>
    <mu2>0.8</mu2>
    <kp>1000000.0</kp>
    <kd>10.0</kd>
  </gazebo>
  <gazebo reference="rear_right_wheel_link">
    <mu1>0.8</mu1>
    <mu2>0.8</mu2>
    <kp>1000000.0</kp>
    <kd>10.0</kd>
  </gazebo>
  
  <!-- 基础坐标系、车身、雷达等（与你的配置一致，略加微调） -->
  <link name="base_footprint"/>
  <joint name="base_footprint_joint" type="fixed">
    <parent link="base_footprint"/>
    <child link="base_link"/>
    <origin xyz="0 0 0.06" rpy="0 0 0"/>
  </joint>
  
  <link name="base_link">
    <visual>
      <geometry><box size="0.4 0.28 0.1"/></geometry>
      <material name="blue"><color rgba="0 0 1 1"/></material>
    </visual>
    <collision><geometry><box size="0.4 0.28 0.1"/></geometry></collision>
    <inertial>
      <mass value="1.2"/>
      <inertia ixx="0.012" ixy="0" ixz="0" iyy="0.012" iyz="0" izz="0.012"/>
    </inertial>
  </link>
  
  <!-- 激光雷达 -->
  <link name="laser_link">
    <visual>
      <geometry><cylinder radius="0.04" length="0.04"/></geometry>
      <origin xyz="0 0 0" rpy="0 0 0"/>
      <material name="red"><color rgba="1 0 0 1"/></material>
    </visual>
    <collision><geometry><cylinder radius="0.04" length="0.04"/></geometry></collision>
    <inertial><mass value="0.05"/><inertia ixx="0.0001" ixy="0" ixz="0" iyy="0.0001" iyz="0" izz="0.0001"/></inertial>
  </link>
  <joint name="laser_joint" type="fixed">
    <parent link="base_link"/>
    <child link="laser_link"/>
    <origin xyz="0.14 0 0.07" rpy="0 0 0"/>
  </joint>
  
  <!-- 前左轮 -->
  <link name="front_left_wheel_link">
    <visual>
      <geometry><cylinder radius="0.05" length="0.04"/></geometry>
      <origin xyz="0 0 0" rpy="1.57079 0 0"/>
      <material name="black"><color rgba="0 0 0 1"/></material>
    </visual>
    <collision><geometry><cylinder radius="0.05" length="0.04"/></geometry><origin xyz="0 0 0" rpy="1.57079 0 0"/></collision>
    <inertial><mass value="0.2"/><inertia ixx="0.0001" ixy="0" ixz="0" iyy="0.0001" iyz="0" izz="0.0001"/></inertial>
  </link>
  <joint name="front_left_wheel_joint" type="continuous">
    <parent link="base_link"/>
    <child link="front_left_wheel_link"/>
    <origin xyz="0.12 0.16 -0.05" rpy="0 0 0"/>
    <axis xyz="0 1 0"/>
  </joint>
  
  <!-- 前右轮 -->
  <link name="front_right_wheel_link">
    <visual>
      <geometry><cylinder radius="0.05" length="0.04"/></geometry>
      <origin xyz="0 0 0" rpy="1.57079 0 0"/>
      <material name="black"><color rgba="0 0 0 1"/></material>
    </visual>
    <collision><geometry><cylinder radius="0.05" length="0.04"/></geometry><origin xyz="0 0 0" rpy="1.57079 0 0"/></collision>
    <inertial><mass value="0.2"/><inertia ixx="0.0001" ixy="0" ixz="0" iyy="0.0001" iyz="0" izz="0.0001"/></inertial>
  </link>
  <joint name="front_right_wheel_joint" type="continuous">
    <parent link="base_link"/>
    <child link="front_right_wheel_link"/>
    <origin xyz="0.12 -0.16 -0.05" rpy="0 0 0"/>
    <axis xyz="0 1 0"/>
  </joint>
  
  <!-- 后左轮（无驱动，仅从动） -->
  <link name="rear_left_wheel_link">
    <visual>
      <geometry><cylinder radius="0.05" length="0.04"/></geometry>
      <origin xyz="0 0 0" rpy="1.57079 0 0"/>
      <material name="black"><color rgba="0 0 0 1"/></material>
    </visual>
    <collision><geometry><cylinder radius="0.05" length="0.04"/></geometry><origin xyz="0 0 0" rpy="1.57079 0 0"/></collision>
    <inertial><mass value="0.2"/><inertia ixx="0.0001" ixy="0" ixz="0" iyy="0.0001" iyz="0" izz="0.0001"/></inertial>
  </link>
  <joint name="rear_left_wheel_joint" type="continuous">
    <parent link="base_link"/>
    <child link="rear_left_wheel_link"/>
    <origin xyz="-0.12 0.16 -0.05" rpy="0 0 0"/>
    <axis xyz="0 1 0"/>
  </joint>
  
  <!-- 后右轮 -->
  <link name="rear_right_wheel_link">
    <visual>
      <geometry><cylinder radius="0.05" length="0.04"/></geometry>
      <origin xyz="0 0 0" rpy="1.57079 0 0"/>
      <material name="black"><color rgba="0 0 0 1"/></material>
    </visual>
    <collision><geometry><cylinder radius="0.05" length="0.04"/></geometry><origin xyz="0 0 0" rpy="1.57079 0 0"/></collision>
    <inertial><mass value="0.2"/><inertia ixx="0.0001" ixy="0" ixz="0" iyy="0.0001" iyz="0" izz="0.0001"/></inertial>
  </link>
  <joint name="rear_right_wheel_joint" type="continuous">
    <parent link="base_link"/>
    <child link="rear_right_wheel_link"/>
    <origin xyz="-0.12 -0.16 -0.05" rpy="0 0 0"/>
    <axis xyz="0 1 0"/>
  </joint>
  
  <!-- 雷达传感器插件（不变） -->
  <gazebo reference="laser_link">
    <sensor name="laser" type="ray">
      <always_on>true</always_on>
      <visualize>true</visualize>
      <update_rate>20</update_rate>
      <pose>0 0 0 0 0 0</pose>
      <ray>
        <scan>
          <horizontal><samples>360</samples><resolution>1</resolution><min_angle>-3.14159</min_angle><max_angle>3.14159</max_angle></horizontal>
        </scan>
        <range><min>0.1</min><max>8.0</max><resolution>0.01</resolution></range>
        <noise><type>gaussian</type><mean>0.0</mean><stddev>0.01</stddev></noise>
      </ray>
      <plugin name="gazebo_ros_laser" filename="libgazebo_ros_ray_sensor.so">
        <ros><remapping>~/out:=scan</remapping></ros>
        <output_type>sensor_msgs/LaserScan</output_type>
        <frame_name>laser_link</frame_name>
      </plugin>
    </sensor>
  </gazebo>

</robot>