<?xml version="1.0"?>
<robot name="box_car" xmlns:xacro="http://www.ros.org/wiki/xacro">

    <material name="blue"><color rgba="0.1 0.1 0.8 1.0"/></material>
    <material name="black"><color rgba="0.0 0.0 0.0 1.0"/></material>
    <material name="red"><color rgba="0.8 0.1 0.1 1.0"/></material>

    <xacro:macro name="box_inertia" params="m x y z">
        <inertial>
            <mass value="${m}"/>
            <inertia ixx="${m*(y*y+z*z)/12}" ixy="0" ixz="0" iyy="${m*(x*x+z*z)/12}" iyz="0" izz="${m*(x*x+y*y)/12}"/>
        </inertial>
    </xacro:macro>

    <xacro:macro name="cylinder_inertia" params="m r h">
        <inertial>
            <mass value="${m}"/>
            <inertia ixx="${m*(3*r*r+h*h)/12}" ixy="0" ixz="0" iyy="${m*(3*r*r+h*h)/12}" iyz="0" izz="${m*r*r/2}"/>
        </inertial>
    </xacro:macro>

    <link name="base_footprint"/>
    
    <joint name="base_footprint_joint" type="fixed">
        <parent link="base_footprint"/>
        <child link="base_link"/>
        <origin xyz="0 0 0.08" rpy="0 0 0"/>
    </joint>

    <link name="base_link">
        <visual>
            <geometry><box size="0.27 0.23 0.10"/></geometry>
            <material name="blue"/>
        </visual>
        <collision>
            <geometry><box size="0.27 0.23 0.10"/></geometry>
        </collision>
        <xacro:box_inertia m="5.0" x="0.27" y="0.23" z="0.10"/>
    </link>
    
    <gazebo reference="base_link">
        <material>Gazebo/Blue</material>
    </gazebo>

    <xacro:macro name="wheel" params="prefix x_reflect y_reflect">
        <link name="${prefix}_wheel">
            <visual>
                <origin xyz="0 0 0" rpy="${pi/2} 0 0"/>
                <geometry><cylinder radius="0.05" length="0.04"/></geometry>
                <material name="black"/>
            </visual>
            <collision>
                <origin xyz="0 0 0" rpy="${pi/2} 0 0"/>
                <geometry><cylinder radius="0.05" length="0.04"/></geometry>
            </collision>
            <xacro:cylinder_inertia m="0.5" r="0.05" h="0.04"/>
        </link>

        <joint name="${prefix}_wheel_joint" type="continuous">
            <parent link="base_link"/>
            <child link="${prefix}_wheel"/>
            <origin xyz="${x_reflect*0.09} ${y_reflect*0.135} -0.03" rpy="0 0 0"/>
            <axis xyz="0 1 0"/>
        </joint>
        
        <gazebo reference="${prefix}_wheel">
            <material>Gazebo/Black</material>
            <mu1>1.0</mu1>
            <mu2>1.0</mu2>
        </gazebo>
    </xacro:macro>

    <xacro:wheel prefix="front_left"  x_reflect="1"  y_reflect="1"/>
    <xacro:wheel prefix="front_right" x_reflect="1"  y_reflect="-1"/>
    <xacro:wheel prefix="rear_left"   x_reflect="-1" y_reflect="1"/>
    <xacro:wheel prefix="rear_right"  x_reflect="-1" y_reflect="-1"/>

    <link name="laser_frame">
        <visual>
            <geometry><cylinder radius="0.03" length="0.04"/></geometry>
            <material name="red"/>
        </visual>
        <collision>
            <geometry><cylinder radius="0.03" length="0.04"/></geometry>
        </collision>
        <xacro:cylinder_inertia m="0.1" r="0.03" h="0.04"/>
    </link>

    <joint name="laser_joint" type="fixed">
        <parent link="base_link"/>
        <child link="laser_frame"/>
        <origin xyz="0.08 0 0.07" rpy="0 0 0"/>
    </joint>
    
    <!-- 旧版 Gazebo 激光雷达插件 -->
    <gazebo reference="laser_frame">
        <material>Gazebo/Red</material>
        <sensor name="gpu_lidar" type="ray">
            <pose>0 0 0 0 0 0</pose>
            <visualize>true</visualize>
            <update_rate>10</update_rate>
            <ray>
                <scan>
                    <horizontal>
                        <samples>360</samples>
                        <resolution>1</resolution>
                        <min_angle>-3.1415926</min_angle>
                        <max_angle>3.1415926</max_angle>
                    </horizontal>
                </scan>
                <range>
                    <min>0.15</min>
                    <max>12.0</max>
                    <resolution>0.01</resolution>
                </range>
                <noise>
                    <type>gaussian</type>
                    <mean>0.0</mean>
                    <stddev>0.01</stddev>
                </noise>
            </ray>
            <plugin name="laser_controller" filename="libgazebo_ros_ray_sensor.so">
                <ros>
                    <argument>~/out:=scan</argument>
                </ros>
                <output_type>sensor_msgs/LaserScan</output_type>
                <frame_name>laser_frame</frame_name>
            </plugin>
        </sensor>
    </gazebo>

    <!-- 差速驱动插件 -->
    <gazebo>
        <plugin name="diff_drive" filename="libgazebo_ros_diff_drive.so">
            <left_joint>front_left_wheel_joint</left_joint>
            <left_joint>rear_left_wheel_joint</left_joint>
            <right_joint>front_right_wheel_joint</right_joint>
            <right_joint>rear_right_wheel_joint</right_joint>
            <wheel_separation>0.27</wheel_separation>
            <wheel_diameter>0.10</wheel_diameter>
            <command_topic>cmd_vel</command_topic>
            <robot_base_frame>base_footprint</robot_base_frame>
        </plugin>
    </gazebo>

</robot>
